sample_data/ETHUSDT/2020-11-01T09-00-00_trades.json
[{"e": "aggTrade", "E": 1604221202545, "s": "ETHUSDT", "a": 171018892, "p": "387.50000000", "q": "2.02000000", "f": 200710055, "l": 200710055, "T": 1604221202544, "m": true, "M": true}, {"e": "aggTrade", "E": 1604221203090, "s": "ETHUSDT", "a": 171018893, "p": "387.50000000", "q": "5.00000000", "f": 200710056, "l": 200710057, "T": 1604221203088, "m": true, "M": true}, {"e": "aggTrade", "E": 1604221204415, "s": "ETHUSDT", "a": 171018894, "p": "387.50000000", "q": "0.02960000", "f": 200710058, "l": 200710058, "T": 1604221204414, "m": false, "M": true}, {"e": "aggTrade", "E": 1604221205382, "s": "ETHUSDT", "a": 171018895, "p": "387.49000000", "q": "2.59780000", "f": 200710059, "l": 200710059, "T": 1604221205380, "m": true, "M": true}, {"e": "aggTrade", "E": 1604221206192, "s": "ETHUSDT", "a": 171018896, "p": "387.49000000", "q": "0.11859000", "f": 200710060, "l": 200710060, "T": 1604221206191, "m": true, "M": true}, {"e": "aggTrade", "E": 1604221207915, "s": "ETHUSDT", "a": 171018897, "p": "387.49000000", "q": "1.86925000", "f": 200710061, "l": 200710061, "T": 1604221207914, "m": true, "M": true}, {"e": "aggTrade", "E": 1604221209987, "s": "ETHUSDT", "a": 171018898, "p": "387.50000000", "q": "0.03779000", "f": 200710062, "l": 200710062, "T": 1604221209986, "m": false, "M": true}, {"e": "aggTrade", "E": 1604221210286, "s": "ETHUSDT", "a": 171018899, "p": "387.50000000", "q": "0.21307000", "f": 200710063, "l": 200710063, "T": 1604221210283, "m": false, "M": true}, {"e": "aggTrade", "E": 1604221210314, "s": "ETHUSDT", "a": 171018900, "p": "387.51000000", "q": "0.25853000", "f": 200710064, "l": 200710064, "T": 1604221210312, "m": false, "M": true}, {"e": "aggTrade", "E": 1604221210339, "s": "ETHUSDT", "a": 171018901, "p": "387.54000000", "q": "0.24999000", "f": 200710065, "l": 200710065, "T": 1604221210332, "m": false, "M": true}, {"e": "aggTrade", "E": 1604221210359, "s": "ETHUSDT", "a": 171018902, "p": "387.56000000", "q": "0.05000000", "f": 200710066, "l": 200710066, "T": 1604221210354, "m": false, "M": true}, {"e": "aggTrade", "E": 1604221210646, "s": "ETHUSDT", "a": 171018903, "p": "387.56000000", "q": "3.03828000", "f": 200710067, "l": 200710067, "T": 1604221210645, "m": true, "M": true}, {"e": "aggTrade", "E": 1604221210659, "s": "ETHUSDT", "a": 171018904, "p": "387.57000000", "q": "0.17071000", "f": 200710068, "l": 200710068, "T": 1604221210658, "m": true, "M": true}, {"e": "aggTrade", "E": 1604221210862, "s": "ETHUSDT", "a": 171018905, "p": "387.59000000", "q": "2.50000000", "f": 200710069, "l": 200710069, "T": 1604221210860, "m": true, "M": true}, {"e": "aggTrade", "E": 1604221211013, "s": "ETHUSDT", "a": 171018906, "p": "387.59000000", "q": "0.04000000", "f": 200710070, "l": 200710070, "T": 1604221211012, "m": true, "M": true}, {"e": "aggTrade", "E": 1604221211564, "s": "ETHUSDT", "a": 171018907, "p": "387.62000000", "q": "0.30601000", "f": 200710071, "l": 200710071, "T": 1604221211562, "m": true, "M": true}, {"e": "aggTrade", "E": 1604221211727, "s": "ETHUSDT", "a": 171018908, "p": "387.63000000", "q": "5.00000000", "f": 200710072, "l": 200710072, "T": 1604221211725, "m": false, "M": true}, {"e": "aggTrade", "E": 1604221211771, "s": "ETHUSDT", "a": 171018909, "p": "387.62000000", "q": "0.04000000", "f": 200710073, "l": 200710073, "T": 1604221211770, "m": true, "M": true}, {"e": "aggTrade", "E": 1604221211980, "s": "ETHUSDT", "a": 171018910, "p": "387.63000000", "q": "0.35000000", "f": 200710074, "l": 200710074, "T": 1604221211978, "m": true, "M": true}, {"e": "aggTrade", "E": 1604221212037, "s": "ETHUSDT", "a": 171018911, "p": "387.64000000", "q": "5.41700000", "f": 200710075, "l": 200710075, "T": 1604221212036, "m": false, "M": true}, {"e": "aggTrade", "E": 1604221212081, "s": "ETHUSDT", "a": 171018912, "p": "387.63000000", "q": "0.04000000", "f": 200710076, "l": 200710076, "T": 1604221212080, "m": true, "M": true}, {"e": "aggTrade", "E": 1604221212227, "s": "ETHUSDT", "a": 171018913, "p": "387.63000000", "q": "3.00000000", "f": 200710077, "l": 200710077, "T": 1604221212225, "m": false, "M": true}, {"e": "aggTrade", "E": 1604221212547, "s": "ETHUSDT", "a": 171018914, "p": "387.64000000", "q": "3.00000000", "f": 200710078, "l": 200710078, "T": 1604221212546, "m": false, "M": true}, {"e": "aggTrade", "E": 1604221212555, "s": "ETHUSDT", "a": 171018915, "p": "387.63000000", "q": "0.06982000", "f": 200710079, "l": 200710079, "T": 1604221212553, "m": true, "M": true}, {"e": "aggTrade", "E": 1604221212631, "s": "ETHUSDT", "a": 171018916, "p": "387.64000000", "q": "0.02900000", "f": 200710080, "l": 200710080, "T": 1604221212630, "m": false, "M": true}, {"e": "aggTrade", "E": 1604221213586, "s": "ETHUSDT", "a": 171018917, "p": "387.63000000", "q": "0.15000000", "f": 200710081, "l": 200710081, "T": 1604221213585, "m": true, "M": true}, {"e": "aggTrade", "E": 1604221213814, "s": "ETHUSDT", "a": 171018918, "p": "387.64000000", "q": "3.11200000", "f": 200710082, "l": 200710082, "T": 1604221213812, "m": false, "M": true}, {"e": "aggTrade", "E": 1604221214581, "s": "ETHUSDT", "a": 171018919, "p": "387.63000000", "q": "0.16000000", "f": 200710083, "l": 200710083, "T": 1604221214580, "m": true, "M": true}, {"e": "aggTrade", "E": 1604221215126, "s": "ETHUSDT", "a": 171018920, "p": "387.63000000", "q": "0.10077000", "f": 200710084, "l": 200710084, "T": 1604221215124, "m": true, "M": true}, {"e": "aggTrade", "E": 1604221215713, "s": "ETHUSDT", "a": 171018921, "p": "387.64000000", "q": "0.00059000", "f": 200710085, "l": 200710085, "T": 1604221215712, "m": false, "M": true}, {"e": "aggTrade", "E": 1604221216181, "s": "ETHUSDT", "a": 171018922, "p": "387.69000000", "q": "2.50000000", "f": 200710086, "l": 200710086, "T": 1604221216180, "m": true, "M": true}, {"e": "aggTrade", "E": 1604221216272, "s": "ETHUSDT", "a": 171018923, "p": "387.65000000", "q": "0.29530000", "f": 200710087, "l": 200710087, "T": 1604221216270, "m": true, "M": true}, {"e": "aggTrade", "E": 1604221216365, "s": "ETHUSDT", "a": 171018924, "p": "387.67000000", "q": "5.00000000", "f": 200710088, "l": 200710088, "T": 1604221216364, "m": false, "M": true}, {"e": "aggTrade", "E": 1604221217002, "s": "ETHUSDT", "a": 171018925, "p": "387.69000000", "q": "0.11219000", "f": 200710089, "l": 200710089, "T": 1604221217001, "m": true, "M": true}, {"e": "aggTrade", "E": 1604221217014, "s": "ETHUSDT", "a": 171018926, "p": "387.69000000", "q": "0.10680000", "f": 200710090, "l": 200710090, "T": 1604221217012, "m": true, "M": true}, {"e": "aggTrade", "E": 1604221217806, "s": "ETHUSDT", "a": 171018927, "p": "387.69000000", "q": "0.18058000", "f": 200710091, "l": 200710091, "T": 1604221217805, "m": true, "M": true}, {"e": "aggTrade", "E": 1604221218309, "s": "ETHUSDT", "a": 171018928, "p": "387.70000000", "q": "2.38253000", "f": 200710092, "l": 200710094, "T": 1604221218308, "m": false, "M": true}, {"e": "aggTrade", "E": 1604221218544, "s": "ETHUSDT", "a": 171018929, "p": "387.69000000", "q": "0.03795000", "f": 200710095, "l": 200710095, "T": 1604221218543, "m": true, "M": true}, {"e": "aggTrade", "E": 1604221220191, "s": "ETHUSDT", "a": 171018930, "p": "387.69000000", "q": "0.10000000", "f": 200710096, "l": 200710096, "T": 1604221220189, "m": true, "M": true}, {"e": "aggTrade", "E": 1604221220543, "s": "ETHUSDT", "a": 171018931, "p": "387.69000000", "q": "0.92282000", "f": 200710097, "l": 200710097, "T": 1604221220542, "m": false, "M": true}, {"e": "aggTrade", "E": 1604221220849, "s": "ETHUSDT", "a": 171018932, "p": "387.69000000", "q": "0.02868000", "f": 200710098, "l": 200710098, "T": 1604221220847, "m": false, "M": true}, {"e": "aggTrade", "E": 1604221223946, "s": "ETHUSDT", "a": 171018933, "p": "387.68000000", "q": "0.16078000", "f": 200710099, "l": 200710099, "T": 1604221223944, "m": true, "M": true}, {"e": "aggTrade", "E": 1604221227143, "s": "ETHUSDT", "a": 171018934, "p": "387.65000000", "q": "4.92880000", "f": 200710100, "l": 200710100, "T": 1604221227142, "m": false, "M": true}, {"e": "aggTrade", "E": 160
