sample_data/ETHUSDT/2020-11-01T10-00-00_trades.json
[{"e": "aggTrade", "E": 1604224800762, "s": "ETHUSDT", "a": 171023592, "p": "385.93000000", "q": "0.30181000", "f": 200715528, "l": 200715528, "T": 1604224800761, "m": true, "M": true}, {"e": "aggTrade", "E": 1604224800766, "s": "ETHUSDT", "a": 171023593, "p": "385.94000000", "q": "0.31134000", "f": 200715529, "l": 200715529, "T": 1604224800765, "m": false, "M": true}, {"e": "aggTrade", "E": 1604224800900, "s": "ETHUSDT", "a": 171023594, "p": "385.94000000", "q": "0.74400000", "f": 200715530, "l": 200715531, "T": 1604224800898, "m": false, "M": true}, {"e": "aggTrade", "E": 1604224801054, "s": "ETHUSDT", "a": 171023595, "p": "385.94000000", "q": "0.03016000", "f": 200715532, "l": 200715532, "T": 1604224801053, "m": false, "M": true}, {"e": "aggTrade", "E": 1604224801112, "s": "ETHUSDT", "a": 171023596, "p": "385.94000000", "q": "0.31900000", "f": 200715533, "l": 200715533, "T": 1604224801110, "m": false, "M": true}, {"e": "aggTrade", "E": 1604224801310, "s": "ETHUSDT", "a": 171023597, "p": "385.94000000", "q": "18.34400000", "f": 200715534, "l": 200715534, "T": 1604224801309, "m": false, "M": true}, {"e": "aggTrade", "E": 1604224801422, "s": "ETHUSDT", "a": 171023598, "p": "385.94000000", "q": "11.38500000", "f": 200715535, "l": 200715536, "T": 1604224801420, "m": false, "M": true}, {"e": "aggTrade", "E": 1604224801770, "s": "ETHUSDT", "a": 171023599, "p": "385.95000000", "q": "0.30150000", "f": 200715537, "l": 200715537, "T": 1604224801769, "m": true, "M": true}, {"e": "aggTrade", "E": 1604224802935, "s": "ETHUSDT", "a": 171023600, "p": "385.95000000", "q": "0.51481000", "f": 200715538, "l": 200715538, "T": 1604224802934, "m": true, "M": true}, {"e": "aggTrade", "E": 1604224803746, "s": "ETHUSDT", "a": 171023601, "p": "385.95000000", "q": "0.10000000", "f": 200715539, "l": 200715539, "T": 1604224803745, "m": false, "M": true}, {"e": "aggTrade", "E": 1604224805645, "s": "ETHUSDT", "a": 171023602, "p": "385.99000000", "q": "0.54900000", "f": 200715540, "l": 200715540, "T": 1604224805644, "m": false, "M": true}, {"e": "aggTrade", "E": 1604224805766, "s": "ETHUSDT", "a": 171023603, "p": "385.98000000", "q": "0.57537000", "f": 200715541, "l": 200715541, "T": 1604224805765, "m": true, "M": true}, {"e": "aggTrade", "E": 1604224806091, "s": "ETHUSDT", "a": 171023604, "p": "385.96000000", "q": "0.31900000", "f": 200715542, "l": 200715542, "T": 1604224806090, "m": false, "M": true}, {"e": "aggTrade", "E": 1604224806349, "s": "ETHUSDT", "a": 171023605, "p": "385.98000000", "q": "0.14340000", "f": 200715543, "l": 200715543, "T": 1604224806348, "m": false, "M": true}, {"e": "aggTrade", "E": 1604224806925, "s": "ETHUSDT", "a": 171023606, "p": "385.94000000", "q": "0.78400000", "f": 200715544, "l": 200715544, "T": 1604224806924, "m": false, "M": true}, {"e": "aggTrade", "E": 1604224807027, "s": "ETHUSDT", "a": 171023607, "p": "385.93000000", "q": "0.59200000", "f": 200715545, "l": 200715545, "T": 1604224807026, "m": false, "M": true}, {"e": "aggTrade", "E": 1604224807139, "s": "ETHUSDT", "a": 171023608, "p": "385.93000000", "q": "0.12147000", "f": 200715546, "l": 200715546, "T": 1604224807138, "m": false, "M": true}, {"e": "aggTrade", "E": 1604224807258, "s": "ETHUSDT", "a": 171023609, "p": "385.96000000", "q": "0.02888000", "f": 200715547, "l": 200715547, "T": 1604224807257, "m": false, "M": true}, {"e": "aggTrade", "E": 1604224810516, "s": "ETHUSDT", "a": 171023610, "p": "385.96000000", "q": "4.41300000", "f": 200715548, "l": 200715548, "T": 1604224810515, "m": true, "M": true}, {"e": "aggTrade", "E": 1604224810640, "s": "ETHUSDT", "a": 171023611, "p": "385.94000000", "q": "3.16400000", "f": 200715549, "l": 200715550, "T": 1604224810639, "m": true, "M": true}, {"e": "aggTrade", "E": 1604224811220, "s": "ETHUSDT", "a": 171023612, "p": "385.94000000", "q": "0.03802000", "f": 200715551, "l": 200715551, "T": 1604224811219, "m": false, "M": true}, {"e": "aggTrade", "E": 1604224811784, "s": "ETHUSDT", "a": 171023613, "p": "385.95000000", "q": "18.57300000", "f": 200715552, "l": 200715553, "T": 1604224811783, "m": true, "M": true}, {"e": "aggTrade", "E": 1604224811898, "s": "ETHUSDT", "a": 171023614, "p": "385.95000000", "q": "1.00000000", "f": 200715554, "l": 200715554, "T": 1604224811897, "m": true, "M": true}, {"e": "aggTrade", "E": 1604224812003, "s": "ETHUSDT", "a": 171023615, "p": "385.95000000", "q": "14.00200000", "f": 200715555, "l": 200715555, "T": 1604224812001, "m": true, "M": true}, {"e": "aggTrade", "E": 1604224812490, "s": "ETHUSDT", "a": 171023616, "p": "385.95000000", "q": "0.06982000", "f": 200715556, "l": 200715556, "T": 1604224812488, "m": true, "M": true}, {"e": "aggTrade", "E": 1604224813244, "s": "ETHUSDT", "a": 171023617, "p": "385.92000000", "q": "0.35843000", "f": 200715557, "l": 200715557, "T": 1604224813243, "m": false, "M": true}, {"e": "aggTrade", "E": 1604224813355, "s": "ETHUSDT", "a": 171023618, "p": "385.92000000", "q": "0.15177000", "f": 200715558, "l": 200715558, "T": 1604224813354, "m": false, "M": true}, {"e": "aggTrade", "E": 1604224813465, "s": "ETHUSDT", "a": 171023619, "p": "385.92000000", "q": "0.03007000", "f": 200715559, "l": 200715559, "T": 1604224813464, "m": false, "M": true}, {"e": "aggTrade", "E": 1604224814190, "s": "ETHUSDT", "a": 171023620, "p": "385.95000000", "q": "1.13000000", "f": 200715560, "l": 200715560, "T": 1604224814189, "m": true, "M": true}, {"e": "aggTrade", "E": 1604224814257, "s": "ETHUSDT", "a": 171023621, "p": "385.95000000", "q": "3.44400000", "f": 200715561, "l": 200715561, "T": 1604224814255, "m": true, "M": true}, {"e": "aggTrade", "E": 1604224816453, "s": "ETHUSDT", "a": 171023622, "p": "385.96000000", "q": "0.18000000", "f": 200715562, "l": 200715562, "T": 1604224816451, "m": false, "M": true}, {"e": "aggTrade", "E": 1604224816470, "s": "ETHUSDT", "a": 171023623, "p": "385.96000000", "q": "0.00046000", "f": 200715563, "l": 200715563, "T": 1604224816469, "m": false, "M": true}, {"e": "aggTrade", "E": 1604224816562, "s": "ETHUSDT", "a": 171023624, "p": "386.03000000", "q": "1.05800000", "f": 200715564, "l": 200715564, "T": 1604224816560, "m": true, "M": true}, {"e": "aggTrade", "E": 1604224816664, "s": "ETHUSDT", "a": 171023625, "p": "386.03000000", "q": "0.19433000", "f": 200715565, "l": 200715565, "T": 1604224816663, "m": true, "M": true}, {"e": "aggTrade", "E": 1604224816777, "s": "ETHUSDT", "a": 171023626, "p": "386.03000000", "q": "0.10500000", "f": 200715566, "l": 200715566, "T": 1604224816775, "m": true, "M": true}, {"e": "aggTrade", "E": 1604224818426, "s": "ETHUSDT", "a": 171023627, "p": "386.04000000", "q": "0.04182000", "f": 200715567, "l": 200715567, "T": 1604224818424, "m": false, "M": true}, {"e": "aggTrade", "E": 1604224818542, "s": "ETHUSDT", "a": 171023628, "p": "386.03000000", "q": "0.02727000", "f": 200715568, "l": 200715568, "T": 1604224818540, "m": true, "M": true}, {"e": "aggTrade", "E": 1604224818715, "s": "ETHUSDT", "a": 171023629, "p": "386.03000000", "q": "0.04772000", "f": 200715569, "l": 200715569, "T": 1604224818714, "m": true, "M": true}, {"e": "aggTrade", "E": 1604224820140, "s": "ETHUSDT", "a": 171023630, "p": "386.03000000", "q": "0.10500000", "f": 200715570, "l": 200715570, "T": 1604224820138, "m": true, "M": true}, {"e": "aggTrade", "E": 1604224820236, "s": "ETHUSDT", "a": 171023631, "p": "386.03000000", "q": "0.45094000", "f": 200715571, "l": 200715571, "T": 1604224820235, "m": true, "M": true}, {"e": "aggTrade", "E": 1604224821620, "s": "ETHUSDT", "a": 171023632, "p": "386.03000000", "q": "0.05420000", "f": 200715572, "l": 200715572, "T": 1604224821619, "m": true, "M": true}, {"e": "aggTrade", "E": 1604224821622, "s": "ETHUSDT", "a": 171023633, "p": "386.03000000", "q": "0.03600000", "f": 200715573, "l": 200715573, "T": 1604224821621, "m": true, "M": true}, {"e": "aggTrade", "E": 1604224821672, "s": "ETHUSDT", "a": 171023634, "p": "386.04000000", "q": "0.18058000", "f": 200715574, "l": 200715574, "T": 1604224821671, "m": false, "M": true}, {"e": "aggTrade", 
